Workbook

Sheet 00_Cover
B2: DENTAL NATION × WEAREFAST.IO
B3: Year-1 Marketing Plan · Spend Capacity · Unlock Map
B4: Prepared for Faisal, Founder — wearefast.io | Prepared by Dental Nation Growth | July 2026
B6: The answer first | C6: Dental Nation runs a proven 5-lane demand engine (2,500 leads/mo → 500 patients → AED 500K/mo) with launch infrastructure fully live. Year-1 spend capacity is AED 5.3M base case. Two partners plug in: wearefast.io closes capability gaps (design pod, video/podcast studio, UGC production, PR), and ArabyAds runs the affiliate/influencer/demand-gen program on a CPL model from next week. This file is the alignment document for that engagement.
B7: Operating principle | C7: Blocked initiatives never stall the programme. They are PARKED with a written resume trigger and effort redeploys to the next-highest-impact active item. See 07_Park Register.
B8: What is already live | C8: Website + LPs live · Ad account structure ready on all platforms · EMR + granular tracking dashboard · Domain control across all clinic sites · 5-lane execution model operating (Lanes B/D/C live, J and E in activation) · Organic posting running.
B9: Known gaps | C9: No dedicated design team · No videographer / podcast content team · Creator/UGC cadence below plan. These are the wearefast.io unlock candidates (06_wearefast Unlocks).
B10: The decision we need | C10: Confirm which unlocks wearefast.io owns and from which month, so the Q-by-Q plan locks and paid spend releases against the gates in 04_Spend Capacity.
B12: HOW TO READ THIS FILE
B13: 01_Executive Summary | C13: The plan, the money, the ask — one screen.
B14: 02_Lane Model | C14: The 5-lane demand engine: funnel math, lane targets, clinic × channel allocation.
B15: 03_Readiness & Gaps | C15: Bandwidth audit: live / partial / gap, and who covers each.
B16: 04_Spend Capacity | C16: Monthly/quarterly envelope, one-time costs, scenarios, return economics.
B17: 05_12M Plan | C17: Quarter-by-quarter execution with DN / FST / ARB ownership and P0–P2 priorities.
B18: 06_wearefast Unlocks | C18: Each gap → what wearefast.io unlocks, when, and the partner ecosystem map.
B19: 07_Park Register | C19: Park/resume logic + current register of blocked items.
B20: 08_Offer Lanes | C20: Canonical offers per lane (DN First Look, DN SOS, DN Plan, DN Scan, DN Glow Up) + creative guardrails.
B21: 09_Commercial Model | C21: Anchor–Ladder economics: arrivals → cases → revenue, with defensible high-value mix.
B22: 10_Actuals Tracker | C22: Plan vs actual spend/CPL by channel (input cells for MTD actuals).
B23: 11_Clinic Capacity | C23: Capacity by clinic, utilisation targets, media throttle rules.
B24: 12_KPIs & Governance | C24: Targets, guardrails, decision protocol, partner cadence, first-meeting agenda.
B25: 13_Assumptions & Sources | C25: Funnel math, CPL basis, and source files behind every number.

Sheet 01_Executive Summary
B2: EXECUTIVE SUMMARY
B3: Answer first: the engine works, capacity is funded, three gaps cap velocity — that is the wearefast.io mandate.
B5: 1. THE OPERATING MODEL (ACTIVE NOW — see 02_Lane Model)
B6: Metric | C6: Value | D6: Note
B7: Qualified leads / month | C7: ='02_Lane Model'!D7 -> 2500 | D7: 5 lanes across 3 clinics: Dr. Tosun 1,000 · Al Wasl 1,000 · AMC 500
B8: New patients / month | C8: ='02_Lane Model'!D10 -> 504 | D8: Funnel: 60% book × 70% show × 48% accept ≈ 20% lead→patient
B9: Revenue / month (AED) | C9: ='02_Lane Model'!D11 -> 504000 | D9: Avg revenue per patient AED 1,000
B10: Annual run rate (AED) | C10: ='02_Lane Model'!D12 -> 6048000 | D10: Monthly × 12
B11: Consistency check: the Rescue-plan funnel (≈20% lead→patient) and the Y1 annual model (20% QL→arrival) converge on the same conversion economics — two independent builds, one answer.
B13: 2. YEAR-1 SPEND CAPACITY (see 04_Spend Capacity)
B14: Metric | C14: Value (AED) | D14: Note
B15: Year-1 paid media envelope | C15: ='04_Spend Capacity'!D19 -> 3494022 | D15: H1 ≈ 1.34M · H2 ≈ 2.15M; released only when gates met
B16: Year-1 organic engine (effort valuation) | C16: ='04_Spend Capacity'!E19 -> 1291606 | D16: SEO/local, referrals, corporate, reactivation, PR
B17: Fixed stack (12 months) | C17: ='04_Spend Capacity'!F19 -> 172200 | D17: AED 14,350/mo tools & tracking run-rate
B18: One-time setup & platform costs | C18: ='04_Spend Capacity'!D41 -> 360000 | D18: Site, tracking, EMR, AI call center, agency onboarding
B19: TOTAL YEAR-1 CAPACITY (BASE) | C19: ='04_Spend Capacity'!D49 -> 5317828 | D19: The number to scope wearefast.io against
B20: Weighted paid CPL target | C20: 161 | D20: ≤150 by Month 6; per-channel basis in 13_Assumptions & Sources
B22: 3. STRENGTHS vs GAPS
B23: Ready today | C23: Gaps → wearefast.io unlocks
B24: · Website live; conversion LPs in place | C24: · Dedicated design pod (ads, LPs, brand kits, motion)
B25: · Ad account structure ready on all platforms | C25: · Videographer / podcast content studio
B26: · EMR + granular tracking dashboard live | C26: · Creator network + UGC production cadence
B27: · 5-lane model operating; Lanes B/D/C live | C27: · PR reach (influencer activation now covered by ArabyAds)
B28: · Domain control across all clinic sites | C28: · Media scale support at higher spend tiers
B30: 4. THE ASK TO FAISAL
B31: Confirm the unlocks in 06_wearefast Unlocks (owner + start month). Anything wearefast.io cannot cover is parked per 07_Park Register — no programme stall. Spend releases per the gates in 04_Spend Capacity; actuals reviewed against 10_Actuals Tracker at every sync.
B33: 5. WHERE WE ARE TODAY (DASHBOARD ACTUALS)
B34: Spend to date (Meta + Google) | C34: ='10_Actuals Tracker'!C7 -> 87370 | D34: Only generic Google Search + GMB (Al Wasl) active; no lane-based paid
B35: Leads / blended CPL | C35: ='10_Actuals Tracker'!C9 -> 361 | D35: 242 leads at AED 361/lead vs AED 161 target — the creative gap, live
B36: Clinic revenue / avg bill | C36: 202000 | D36: AED 941 avg bill validates the commercial model input
B37: Annual value of creative unlock (AED) | C37: ='10_Actuals Tracker'!C22 -> 4340400 | D37: What closing the CPL gap is worth per year — the wearefast.io business case in one number

Sheet 02_Lane Model
B2: THE 5-LANE DEMAND ENGINE
B3: Active operating model (Revenue Rescue Plan). Blue = editable assumptions; black = formulas.
B5: A. GROUP FUNNEL (MONTHLY)
B6: Stage | C6: Rate | D6: Volume | F6: Per day (÷30)
B7: Qualified leads | C7: — | D7: 2500 | F7: =ROUND(D7/30,0) -> 83 | H7: 83/day across 3 clinics
B8: Booked | C8: 0.6 | D8: =ROUND(D7*C8,0) -> 1500 | F8: =ROUND(D8/30,0) -> 50 | H8: Front desk 5-min response + mandatory booking script (Lanie)
B9: Showed | C9: 0.7 | D9: =ROUND(D8*C9,0) -> 1050 | F9: =ROUND(D9/30,0) -> 35 | H9: Show-rate protocol + WhatsApp reminders
B10: Paying patients | C10: 0.48 | D10: =ROUND(D9*C10,0) -> 504 | F10: =ROUND(D10/30,0) -> 17 | H10: Treatment acceptance (TC discipline)
B11: Revenue / month (AED) | C11: 1000 | D11: =D10*C11 -> 504000 | F11: =ROUND(D11/30,0) -> 16800 | H11: Rate column = avg revenue per patient
B12: Annual run rate (AED) | C12: ×12 | D12: =D11*12 -> 6048000
B14: B. LANE TARGETS (2,500 LEADS/MONTH)
B15: Lane | C15: Share | D15: Leads/mo | E15: Rev/mo (AED) | F15: Primary clinic | G15: Hook offer | H15: Status / activation
B16: Lane B — Family & Routine | C16: 0.35 | D16: =ROUND($D$7*C16,0) -> 875 | E16: =ROUND($D$11*C16,0) -> 176400 | F16: Dr. Tosun | G16: New Patient Welcome Check @ 799 AED | H16: LIVE — Week 1
B17: Lane D — Emergency | C17: 0.2 | D17: =ROUND($D$7*C17,0) -> 500 | E17: =ROUND($D$11*C17,0) -> 100800 | F17: AMC | G17: Emergency Fast-Track @ 699 AED | H17: LIVE — Week 1
B18: Lane C — Implants | C18: 0.2 | D18: =ROUND($D$7*C18,0) -> 500 | E18: =ROUND($D$11*C18,0) -> 100800 | F18: Al Wasl | G18: Smile in a Day — free CBCT (value 899) | H18: LIVE — Week 1
B19: Lane J — Ortho | C19: 0.2 | D19: =ROUND($D$7*C19,0) -> 500 | E19: =ROUND($D$11*C19,0) -> 100800 | F19: All clinics | G19: Ortho Smile Assessment @ 499 AED | H19: Always-on — Week 2–3
B20: Lane E — Lifestyle (Smile Bar) | C20: 0.05 | D20: =ROUND($D$7*C20,0) -> 125 | E20: =ROUND($D$11*C20,0) -> 25200 | F20: Smile Bar | G20: Whitening Flash @ 1,699 AED | H20: Soft launch — Week 2–3
B21: Total | C21: =SUM(C16:C20) -> 1 | D21: =SUM(D16:D20) -> 2500 | E21: =SUM(E16:E20) -> 504000
B23: C. CLINIC × CHANNEL ALLOCATION (LEADS/MONTH)
B24: Clinic | C24: Total leads | D24: Digital 70% | E24: · Google 40% | F24: · Meta 30% | G24: · Influencer 30% | H24: Reactivation 15% / B2B 15%
B25: Dr. Tosun | C25: 1000 | D25: =ROUND(C25*0.7,0) -> 700 | E25: =ROUND(D25*0.4,0) -> 280 | F25: =ROUND(D25*0.3,0) -> 210 | G25: =ROUND(D25*0.3,0) -> 210 | H25: =ROUND(C25*0.15,0)&" / "&ROUND(C25*0.15,0) -> 150 / 150
B26: DN Al Wasl | C26: 1000 | D26: =ROUND(C26*0.7,0) -> 700 | E26: =ROUND(D26*0.4,0) -> 280 | F26: =ROUND(D26*0.3,0) -> 210 | G26: =ROUND(D26*0.3,0) -> 210 | H26: =ROUND(C26*0.15,0)&" / "&ROUND(C26*0.15,0) -> 150 / 150
B27: AMC | C27: 500 | D27: =ROUND(C27*0.7,0) -> 350 | E27: =ROUND(D27*0.4,0) -> 140 | F27: =ROUND(D27*0.3,0) -> 105 | G27: =ROUND(D27*0.3,0) -> 105 | H27: =ROUND(C27*0.15,0)&" / "&ROUND(C27*0.15,0) -> 75 / 75
B28: Group | C28: =SUM(C25:C27) -> 2500 | D28: =SUM(D25:D27) -> 1750 | E28: =SUM(E25:E27) -> 700 | F28: =SUM(F25:F27) -> 525 | G28: =SUM(G25:G27) -> 525
B30: Ownership: Digital — Fahad + agency (wearefast.io). Reactivation — Lanie + clinic managers. B2B — Commercial Lead. Accountable: Dr. Luvi. Approval: Mr. Akbar (CEO). Deadline enforcement: Gautam (TMO).

Sheet 03_Readiness & Gaps
B2: READINESS & BANDWIDTH AUDIT
B3: What we execute in-house today vs where capacity is missing.
B5: Capability | C5: Status | D5: Detail | E5: Covered today by | F5: What wearefast.io can unlock
B6: Website & landing pages | C6: LIVE | D6: dentalnation.ae live with conversion-first LPs; lane offer pages delivered to agency for LP design. | E6: In-house (Fahad) | F6: CRO support + LP variants at campaign velocity.
B7: Ad account structure | C7: LIVE | D7: Full architecture ready across Google, Meta, TikTok, YouTube: 12 Google campaigns, 8–10 Meta ad sets, naming, audiences, exclusions. | E7: In-house (Fahad) | F7: Media scale support once monthly spend passes ~AED 300K.
B8: Tracking & measurement | C8: LIVE | D8: EMR + fully functional dashboard, granular attribution (GA4, sGTM, call tracking, WA events). | E8: In-house (Fahad) | F8: — (wearefast.io gets read access).
B9: 5-lane execution model | C9: PARTIAL | D9: Lane model live on ORGANIC social; paid lane campaigns PARKED on creative blocker. Only generic Google Search + GMB (Al Wasl) running paid. Actual blended CPL AED 361 vs 161 target — see 10_Actuals Tracker. | E9: Full DN team | F9: Creative fuel per lane (see gaps below).
B10: Domain & platform control | C10: LIVE | D10: All clinic websites and domains consolidated; DNS/SSL managed. | E10: In-house | F10: —
B11: Organic social | C11: PARTIAL | D11: Posting bits and pieces; cadence below 3 posts/week target. | E11: In-house, ad hoc | F11: Content engine: calendar, production, editing.
B12: Design capability | C12: GAP | D12: No dedicated design team. CONFIRMED as the live blocker: paid lane campaigns cannot launch; current generic-only paid runs at AED 361 CPL (2.2x target). | E12: Not covered | F12: Dedicated design pod — highest-priority unlock.
B13: Videography & podcast production | C13: GAP | D13: No videographer. Video content, podcasts, doctor authority content, before/after films, lane-specific reels all unstaffed. | E13: Not covered | F13: Video/podcast studio — content engine for Meta reels, influencer collabs, YouTube, Lane C authority content.
B14: Content creators / UGC | C14: GAP | D14: UGC production for paid creative not staffed (plan calls for 1 reel + 3 stories per creator). ArabyAds covers influencer ACTIVATION; content PRODUCTION remains the gap. | E14: Not covered | F14: Creator network + UGC production for paid creative.
B15: Influencer / affiliate demand gen | C15: ACTIVATING | D15: ArabyAds contracted as affiliate/influencer/demand-gen partner (CPL-based); execution starts next week. PR agency still not finalised. | E15: ArabyAds (from next week) | F15: wearefast.io: PR placements + creative feed for ArabyAds campaigns.
B16: WhatsApp / CRM automation | C16: PARTIAL | D16: WA Business API live; reactivation blasts running (Lanie); journey automation partially built. | E16: In-house (Fahad) + Lanie | F16: Optional: CRM ops support; not a launch blocker.
B17: Call handling / TC conversion | C17: PARTIAL | D17: Front desk scripts + 5-min response protocol live; 3-attempt protocol on unconverted leads; AI call management contracted. | E17: Lanie + ops | F17: Optional: call-center QA framework.
B19: Read: launch is NOT blocked — the engine is live and converting. The three gaps (design, video/podcast, creators) cap creative volume, which caps how hard paid can scale. That is precisely the wearefast.io mandate.

Sheet 04_Spend Capacity
B2: SPEND CAPACITY — YEAR 1
B3: Blue = plan inputs (editable). Black = formulas. All values AED.
B5: A. MONTHLY ENVELOPE (BASE CASE)
B6: Month | C6: Qtr | D6: Paid Media | E6: Organic Engine | F6: Fixed Stack | G6: Total | H6: Paid QLs | I6: Note
B7: M1 | C7: Q1 | D7: 168406 | E7: 42084 | F7: 14350 | G7: =SUM(D7:F7) -> 224840 | H7: =ROUND(D7/$D$52,0) -> 1046 | I7: Rescue-phase live: Lanes B/D/C campaigns running; Lane J/E activating
B8: M2 | C8: Q1 | D8: 185150 | E8: 46345 | F8: 14350 | G8: =SUM(D8:F8) -> 245845 | H8: =ROUND(D8/$D$52,0) -> 1150 | I8: Stabilise Search & PMax; first A/B tests; Lane E soft launch
B9: M3 | C9: Q1 | D9: 207690 | E9: 51876 | F9: 14350 | G9: =SUM(D9:F9) -> 273916 | H9: =ROUND(D9/$D$52,0) -> 1290 | I9: Influencer activation wave (15–20 micro, 3–5 macro)
B10: M4 | C10: Q2 | D10: 249550 | E10: 77217 | F10: 14350 | G10: =SUM(D10:F10) -> 341117 | H10: =ROUND(D10/$D$52,0) -> 1550 | I10: Scale winners; YouTube Action; site v2 starts
B11: M5 | C11: Q2 | D11: 257278 | E11: 79684 | F11: 14350 | G11: =SUM(D11:F11) -> 351312 | H11: =ROUND(D11/$D$52,0) -> 1598 | I11: Audience layering; referral program
B12: M6 | C12: Q2 | D12: 273056 | E12: 84468 | F12: 14350 | G12: =SUM(D12:F12) -> 371874 | H12: =ROUND(D12/$D$52,0) -> 1696 | I12: OOH/radio test only if Net CPL ≤ 150
B13: M7 | C13: Q3 | D13: 350336 | E13: 133055 | F13: 14350 | G13: =SUM(D13:F13) -> 497741 | H13: =ROUND(D13/$D$52,0) -> 2176 | I13: Media scale support engages (spend > 300K/mo)
B14: M8 | C14: Q3 | D14: 350336 | E14: 133055 | F14: 14350 | G14: =SUM(D14:F14) -> 497741 | H14: =ROUND(D14/$D$52,0) -> 2176 | I14: Referral & membership program live
B15: M9 | C15: Q3 | D15: 360801 | E15: 137166 | F15: 14350 | G15: =SUM(D15:F15) -> 512317 | H15: =ROUND(D15/$D$52,0) -> 2241 | I15: Aligner finance plan pushes elective mix
B16: M10 | C16: Q4 | D16: 360157 | E16: 167216 | F16: 14350 | G16: =SUM(D16:F16) -> 541723 | H16: =ROUND(D16/$D$52,0) -> 2237 | I16: Always-on recall & retention automation
B17: M11 | C17: Q4 | D17: 360157 | E17: 167216 | F17: 14350 | G17: =SUM(D17:F17) -> 541723 | H17: =ROUND(D17/$D$52,0) -> 2237 | I17: Corporate renewals & upsells
B18: M12 | C18: Q4 | D18: 371105 | E18: 172224 | F18: 14350 | G18: =SUM(D18:F18) -> 557679 | H18: =ROUND(D18/$D$52,0) -> 2305 | I18: Influencer tiers + case-study content expanded
B19: Y1 | D19: =SUM(D7:D18) -> 3494022 | E19: =SUM(E7:E18) -> 1291606 | F19: =SUM(F7:F18) -> 172200 | G19: =SUM(G7:G18) -> 4957828 | H19: =SUM(H7:H18) -> 21702 | I19: Total year-1 running envelope (excl. one-time)
B21: B. QUARTERLY ROLLUP
B22: Quarter | D22: Paid Media | E22: Organic | F22: Fixed | G22: Total | H22: Paid QLs | I22: Paid share of QLs
B23: Q1 | D23: =SUMIFS(D$7:D$18,$C$7:$C$18,$B23) -> 561246 | E23: =SUMIFS(E$7:E$18,$C$7:$C$18,$B23) -> 140305 | F23: =SUMIFS(F$7:F$18,$C$7:$C$18,$B23) -> 43050 | G23: =SUMIFS(G$7:G$18,$C$7:$C$18,$B23) -> 744601 | H23: =SUMIFS(H$7:H$18,$C$7:$C$18,$B23) -> 3486 | I23: 65% (tapers as organic ramps)
B24: Q2 | D24: =SUMIFS(D$7:D$18,$C$7:$C$18,$B24) -> 779884 | E24: =SUMIFS(E$7:E$18,$C$7:$C$18,$B24) -> 241369 | F24: =SUMIFS(F$7:F$18,$C$7:$C$18,$B24) -> 43050 | G24: =SUMIFS(G$7:G$18,$C$7:$C$18,$B24) -> 1064303 | H24: =SUMIFS(H$7:H$18,$C$7:$C$18,$B24) -> 4844 | I24: 60% (tapers as organic ramps)
B25: Q3 | D25: =SUMIFS(D$7:D$18,$C$7:$C$18,$B25) -> 1061473 | E25: =SUMIFS(E$7:E$18,$C$7:$C$18,$B25) -> 403276 | F25: =SUMIFS(F$7:F$18,$C$7:$C$18,$B25) -> 43050 | G25: =SUMIFS(G$7:G$18,$C$7:$C$18,$B25) -> 1507799 | H25: =SUMIFS(H$7:H$18,$C$7:$C$18,$B25) -> 6593 | I25: 55% (tapers as organic ramps)
B26: Q4 | D26: =SUMIFS(D$7:D$18,$C$7:$C$18,$B26) -> 1091419 | E26: =SUMIFS(E$7:E$18,$C$7:$C$18,$B26) -> 506656 | F26: =SUMIFS(F$7:F$18,$C$7:$C$18,$B26) -> 43050 | G26: =SUMIFS(G$7:G$18,$C$7:$C$18,$B26) -> 1641125 | H26: =SUMIFS(H$7:H$18,$C$7:$C$18,$B26) -> 6779 | I26: 50% (tapers as organic ramps)
B28: C. ONE-TIME SETUP & PLATFORM COSTS
B29: Item | D29: AED
B30: Website design & build (LP v1 + v2) | D30: 22000
B31: Tracking stack (GA4, sGTM, CallGear, CAPI, TikTok API) | D31: 12000
B32: WhatsApp Business API setup & templates | D32: 3000
B33: Brand photography & video shoot (1x) | D33: 15000
B34: Compliance & approvals (DHA/MOHAP assets) | D34: 3000
B35: Creative asset production (ads, LP variants) | D35: 10000
B36: Agency / wearefast.io onboarding (scope negotiable) | D36: 150000
B37: iHealth EMR | D37: 70000
B38: IT solutions | D38: 30000
B39: AI call center | D39: 15000
B40: Other opex | D40: 30000
B41: One-time total | D41: =SUM(D30:D40) -> 360000
B43: D. TOTAL YEAR-1 CAPACITY & SCENARIOS
B44: Scenario | D44: Multiplier | E44: Total capacity (AED) | G44: What changes
B45: Conservative | D45: 0.7 | E45: =ROUND((G$19)*D45,0)+D$41 -> 3830480 | G45: Hold paid at H1 run-rate longer; delay TikTok/YouTube scale; organic carries more.
...

Sheet 05_12M Plan
B2: 12-MONTH EXECUTION PLAN
B3: Owner key: DN = Dental Nation · FST = wearefast.io · ARB = ArabyAds · JNT = joint. Shaded = active quarters. Lanes per 02_Lane Model.
B5: Workstream | C5: Owner | D5: Q1 | E5: Q2 | F5: Q3 | G5: Q4 | H5: Gate / dependency | I5: If blocked → park action | J5: Priority
B6: Lanes B/D/C paid engines (Search + Meta, offer-led) | C6: DN | H6: PARKED on creative — generic Search + GMB (Al Wasl) interim; resume on design pod + asset batch | I6: Interim: generic search continues; lanes stay organic-social | J6: P0
B7: Lane J (Ortho) always-on activation | C7: DN | H7: Scan slots published (8/wk/clinic) + scripts trained | I7: Hold at assessment-offer only; park aligner campaigns | J7: P1
B8: Lane E (Smile Bar) launch + influencer engine | C8: JNT | H8: wearefast.io creator network live (Lane E is 60% IG/TikTok) | I8: Park Lane E paid; keep walk-in/POS only | J8: P1
B9: ArabyAds: affiliate / influencer / CPL demand-gen program | C9: ARB | H9: Contract signed; execution starts next week. Pays on CPL — awareness + influencer + affiliate leads | I9: CPL guardrail: pause placements if lead quality (booking rate) drops below 40% for 2 weeks | J9: P0
B10: Design pod: ads, LP variants, brand kits | C10: FST | H10: wearefast.io design unlock confirmed (M1–M2) | I10: Park scaled creative testing; run on existing assets | J10: P0
B11: Videography & podcast studio | C11: FST | H11: wearefast.io video unlock: reels, doctor authority films, podcast series | I11: Park video content; substitute static + testimonial reviews | J11: P0
B12: UGC / creator content production (for paid creative) | C12: FST | H12: wearefast.io production pod; influencer ACTIVATION runs via ArabyAds (row above) | I12: Park influencer channel (30% of digital); shift to Google/Meta | J12: P1
B13: Content engine: 3 posts/wk + blogs | C13: JNT | H13: Video studio + DN editorial gate | I13: Reduce to sustainable cadence; keep GBP | J13: P1
B14: YouTube Action remarketing | C14: DN | H14: Video assets from wearefast.io studio | I14: Park; remarketing on Meta only | J14: P2
B15: Website v2: treatment hubs + schema | C15: DN | H15: Design pod bandwidth for templates | I15: Park v2; keep converting on v1 LPs | J15: P1
B16: PR placements + brand announcement | C16: FST | H16: wearefast.io PR network confirmed | I16: Park PR; lean on reviews + GBP | J16: P2
B17: B2B wave: 25–30 partners (corporate/spa/gym/schools) | C17: DN | H17: Packages + price lists approved by CEO | I17: Keep inbound handling; park outbound | J17: P1
... B20: Always-on recall & retention automation | C20: DN | H20: WA journey automation complete | I20: Park automation; manual recall (Lanie 3-attempt protocol) | J20: P1

Sheet 06_wearefast Unlocks
B2: WHAT WEAREFAST.IO UNLOCKS, AND WHEN
B3: Each unlock maps to a gap in 03_Readiness & Gaps and releases specific lanes/workstreams in 05_12M Plan.
B5: Unlock (wearefast.io-owned) | C5: Gap it closes | D5: Target start | E5: What it releases | F5: If NOT unlocked (park consequence)
B6: Dedicated design pod (ads, LPs, motion, brand kits) | C6: No dedicated design team | D6: Month 1–2 | E6: Creative testing velocity across all 5 lanes; LP variants for CRO; brand-consistent assets for 3 clinics | F6: Creative volume capped → paid scales slower; site v2 parked; testing limited to existing assets
B7: Videography & podcast studio | C7: No videographer / content team | D7: Month 1–2 | E7: Meta reels (30% of digital), doctor authority films (Lane C before/after), podcast series for brand trust, Lane E social content | F7: Video-led channels underfed; Lane C authority content parked; proof leans on reviews + credentials only
B8: UGC & creator content production | C8: Creator content production unstaffed | D8: Month 2 | E8: Creative feed for the influencer channel (activation via ArabyAds); Lane E launch content (60% IG/TikTok); Lane J teen/parent assets | F8: ArabyAds runs on partner-supplied creative only — lower volume, higher CPL; Lane E launch delayed
B9: PR placements + brand announcement wave | C9: No PR agency finalised | D9: Month 4 (Q2) | E9: Health/lifestyle trust signals; DIFC/flagship launch amplification | F9: PR parked; trust via reviews/GBP only — slower premium perception
B10: Performance media scale support | C10: Solo in-house media operator | D10: Spend > AED 300K/mo (≈M7) | E10: H2 scale to AED 350–370K/mo paid without quality loss; faster test-iterate loops | F10: H2 spend held at H1 ceiling; Y1 new-patient target re-based downward
B11: Campaign film production (quarterly bursts) | C11: One-off shoot budget only | D11: Quarterly | E11: Launch films, YouTube assets, seasonal pushes | F11: YouTube Action parked; campaigns run static-only
B13: Sequencing logic: design pod + video studio first (they gate creative for every lane), creators second (they gate the influencer 30% and Lane E), PR and media-scale support after the engine proves CPL ≤ 150.
B15: PARTNER ECOSYSTEM — WHO DOES WHAT
B16: Partner | C16: Role | D16: Commercial model | E16: Starts | F16: Interfaces with
B17: Dental Nation (in-house) | C17: Strategy, media buying, tracking/attribution, lane ops, reactivation, B2B | D17: Salaried team | E17: Live | F17: Owns the dashboard; briefs both partners
B18: wearefast.io (Faisal) | C18: Capability unlocks: design pod, video/podcast studio, UGC production, PR, media scale support | D18: Retainer + scoped deliverables (onboarding line negotiable) | E18: On confirmation (this file) | F18: Feeds creative to DN paid engines AND ArabyAds campaigns
B19: ArabyAds | C19: Affiliate + influencer + demand-gen / awareness program | D19: CPL-based (performance) | E19: Next week | F19: Receives creative from wearefast.io; leads land in DN tracking with source tags
B20: Design principle: performance risk sits with ArabyAds (CPL), capability risk sits with wearefast.io (deliverables), and measurement truth sits with DN (one dashboard, source-tagged). No partner grades their own homework.

Sheet 07_Park Register
B2: PARK / RESUME REGISTER
B3: The rule that keeps the programme moving when an initiative is blocked.
B5: THE RULE
B6: 1. Blocked >2 weeks by a dependency we cannot resolve → the initiative is PARKED, not dragged.
B7: 2. Every park entry gets a written RESUME TRIGGER — the specific condition that reactivates it.
B8: 3. Freed effort redeploys immediately to the next-highest-impact ACTIVE workstream in 05_12M Plan.
B9: 4. Parked ≠ cancelled. Register reviewed at every bi-weekly wearefast.io sync; trigger met → item resumes.
B11: CURRENT REGISTER
B12: Initiative | C12: Blocker | D12: Status | E12: Resume trigger | F12: Effort redeployed to
B13: Scaled creative testing program | C13: No design team | D13: PARKED | E13: wearefast.io design pod onboarded (M1–M2) | F13: Paid runs on existing asset library
B14: Video & podcast content engine | C14: No videographer | D14: PARKED | E14: wearefast.io video studio live; first reel batch delivered | F14: Static creative + testimonial reviews
B15: Influencer / affiliate channel (30% of digital) | C15: Was: no activation partner — RESOLVED via ArabyAds | D15: ACTIVATING | E15: ArabyAds execution starts next week; full status review after first 2 weeks of CPL data | F15: — (unparked; creative production gap remains with wearefast.io)
B16: Lane E (Smile Bar) full launch | C16: Depends on creator + video content | D16: GATED | E16: ArabyAds influencer activation live + wearefast.io content batch delivered | F16: Walk-in/POS + in-clinic signage
B17: Full content cadence (3/wk + blogs) | C17: Content production unstaffed | D17: PARTIAL | E17: wearefast.io content engine live | F17: Sustainable GBP + core social cadence
B18: PR & brand announcement wave | C18: No PR agency finalised | D18: PARKED | E18: wearefast.io PR network scoped and priced | F18: Reviews engine + GBP optimisation
B19: OOH / radio test | C19: Gated by performance | D19: GATED | E19: M3 Net CPL ≤ AED 150 AND capacity 65–85% | F19: Digital channels until gate met
B20: Lane-based PAID campaigns (B/D/C offers) | C20: Creative blocker — no design/asset production | D20: PARKED | E20: wearefast.io design pod live + first lane asset batch approved | F20: Generic Google Search + GMB (Al Wasl) carries paid; lanes run on ORGANIC social
B21: Reactivation blasts (Lanie, 2x/week) | C21: — | D21: ACTIVE | E21: — | F21: —
B22: Tracking, dashboard, attribution | C22: — | D22: ACTIVE | E22: — | F22: —
B30: Generic Google Search + GMB (Al Wasl) | C30: — | D30: ACTIVE | E30: Transitions to lane-offer campaigns once creative unlocks land | F30: —

Sheet 08_Offer Lanes
B2: CANONICAL OFFER LANES
B3: One offer · one promise · one price · one CTA per lane. Premium-but-accessible, never discount-led.
B5: Lane | C5: Canonical offer | D5: Promise | E5: Price (AED) | F5: CTA | G5: Launch | H5: Assets needed | I5: Dependency | J5: Partner unlock
B6: B | C6: The DN First Look | D6: Full exam + digital X-ray + scale & polish, all-in bundle | E6: 799 | F6: Book The DN First Look | G6: LIVE | H6: Static, carousel, story, WhatsApp card, GBP post, LP module | I6: Design pod + clinic photo set | J6: wearefast.io: creative translation + asset templates
B7: D | C7: DN SOS — Seen in 60 | D7: Same-day exam + X-ray + pain-relief consult; 60-minute guaranteed window | E7: 699 (+200 deposit) | F7: Book DN SOS | G7: LIVE | H7: Search LP, CTWA card, symptom-led carousel, click-to-call GBP | I7: Ops capacity + appointment-window governance | J7: wearefast.io: copy QA (certainty & speed, never fear imagery)
B8: C | C8: The DN Plan | D8: Free CBCT scan + specialist consult + written all-inclusive treatment plan | E8: FREE (value 899) | F8: Get The DN Plan | G8: LIVE | H8: Implant planning LP, transparent-plan carousel, calm education, GBP proof | I8: Clinical imaging & consent SOP (DN clinical) + authority video content (wearefast.io) | J8: wearefast.io: doctor authority films + case-study templates
B9: J | C9: The DN Scan | D9: Digital scan + specialist consult + same-session treatment plan | E9: 499 (deducted if treatment starts ≤30 days) | F9: Book The DN Scan | G9: Wk 2–3 | H9: Scan-to-plan LP, carousel, screen-led reel, deduction-note card | I9: Scanner workflow + specialist calendar (8 slots/wk/clinic) | J9: ArabyAds: teen/parent influencer reach · wearefast.io: reels
B10: E | C10: The DN Glow Up | D10: 60-min laser whitening + complimentary digital smile scan | E10: 1,699 | F10: Book The DN Glow Up | G10: Wk 2–3 | H10: Premium hero, ritual reel, WhatsApp card, clinic ambience photos | I10: Design pod + tasteful photo/video (wellness ritual, not whitening discount) | J10: ArabyAds: lifestyle influencer activation · wearefast.io: content
B12: CREATIVE GUARDRAILS
B13: One offer / one promise / one price / one CTA | E13: Each LP hero, static, carousel opener and WhatsApp card carries a single job.
B14: Premium-but-accessible, not discount-led | E14: No flash-sale language, miracle claims, or fake luxury.
B15: Real clinic proof for local/GBP | E15: GBP posts use clinic/place images, not graphics-only posts.
B16: Assets match operational reality | E16: Never publish DN SOS or DN Plan claims the clinic cannot fulfil.
B17: DHA/MOHAP + consent compliance | E17: Claims, before/after and diagnostic imagery approved and logged before any paid use.

Sheet 09_Commercial Model
B2: ANCHOR–LADDER COMMERCIAL MODEL
B3: Anchor offers bring patients in; the ladder converts them to treatment plans. Blue = inputs. High-value mix input fixes the overcount in earlier drafts.
B5: INPUTS
B6: Input | C6: Value | I6: Basis
B7: QL → arrival rate | C7: 0.2 | I7: 25% booking × 80% show (base model)
B8: Anchor → Ladder conversion | C8: 0.4 | I8: Share of arrivals moving into a treatment plan
B9: Case acceptance | C9: 0.6 | I9: Share of ladder plans accepted
B10: High-value case mix | C10: 0.15 | I10: Share of accepted cases at the high-value ticket (implants/full-arch/aligners)
B11: Avg ladder value (standard case) | C11: 1200 | I11: Anchor–Ladder benchmark
B12: High-value ticket | C12: 10000 | I12: Implant/full-arch/smile-makeover average
B13: Avg first-instance revenue / arrival | C13: 941 | I13: ACTUAL avg bill from Zavis dashboard (was 1,000 planning assumption)
B14: Membership offer rate | C14: 0.9 | I14: Offered at treatment close
B15: Membership enrollment | C15: 0.35 | I15: Target share of offers accepted
B17: QUARTERLY MODEL (Y1)
B18: Quarter | C18: Total QLs | D18: Arrivals | E18: Cases accepted | F18: First-instance rev | G18: Total identified rev | H18: Membership enrollments | I18: Note
B19: Q1 | C19: 5363 | D19: =ROUND(C19*$C7,0) -> 1073 | E19: =ROUND(D19*$C8*$C9,0) -> 258 | F19: =ROUND(D19*$C13,0) -> 1009693 | G19: =E19*$C10*$C12 + E19*(1-$C10)*$C11 + F19 -> 1659853 | H19: =ROUND(E19*$C14*$C15,0) -> 81
B20: Q2 | C20: 8073 | D20: =ROUND(C20*$C7,0) -> 1615 | E20: =ROUND(D20*$C8*$C9,0) -> 388 | F20: =ROUND(D20*$C13,0) -> 1519715 | G20: =E20*$C10*$C12 + E20*(1-$C10)*$C11 + F20 -> 2497475 | H20: =ROUND(E20*$C14*$C15,0) -> 122
B21: Q3 | C21: 11988 | D21: =ROUND(C21*$C7,0) -> 2398 | E21: =ROUND(D21*$C8*$C9,0) -> 576 | F21: =ROUND(D21*$C13,0) -> 2256518 | G21: =E21*$C10*$C12 + E21*(1-$C10)*$C11 + F21 -> 3708038 | H21: =ROUND(E21*$C14*$C15,0) -> 181
B22: Q4 | C22: 13557 | D22: =ROUND(C22*$C7,0) -> 2711 | E22: =ROUND(D22*$C8*$C9,0) -> 651 | F22: =ROUND(D22*$C13,0) -> 2551051 | G22: =E22*$C10*$C12 + E22*(1-$C10)*$C11 + F22 -> 4191571 | H22: =ROUND(E22*$C14*$C15,0) -> 205
B23: Y1 | C23: =SUM(C19:C22) -> 38981 | D23: =SUM(D19:D22) -> 7797 | E23: =SUM(E19:E22) -> 1873 | F23: =SUM(F19:F22) -> 7336977 | G23: =SUM(G19:G22) -> 12056937 | H23: =SUM(H19:H22) -> 589 | I23: Total identified revenue feeds return economics in 04_Spend Capacity
B25: Logic fix vs earlier draft: high-value revenue applies only to the high-value MIX of accepted cases (input above), not to every accepted case. This turns an indefensible AED ~18.7M 'potential' into a number that survives diligence.

Sheet 10_Actuals Tracker
B2: ACTUALS — WHERE WE ARE TODAY
B3: Dashboard snapshot (Zavis CRM + ad platforms, Jul 2026). Yellow = update at each sync.
B5: A. CURRENT STATE SNAPSHOT
B6: Metric | C6: Actual | E6: Read
B7: Marketing spend to date (Meta + Google) | C7: 87370 | E7: Only generic Google Search + GMB ads (Al Wasl) currently active; no lane-based paid campaigns
B8: Leads generated | C8: 242 | E8: From generic campaigns — no offer-led creative
B9: Blended CPL (actual) | C9: =ROUND(C7/C8,0) -> 361 | E9: AED 361/lead vs AED 161 plan target — 2.2x over. This is the cost of running WITHOUT lane offers and creative
B10: Appointments booked | C10: 296 | E10: Includes recall/walk-in/direct — NOT all from the 242 marketing leads. 5 booked by AI agent
B11: Appointments completed | C11: 39 | E11: 42% of concluded — period/definition to be confirmed before reading a show rate from this
B12: Clinic revenue (AED) | C12: 202000 | E12: Business is converting — the engine works
B13: Average bill (AED) | C13: 941 | E13: Validates the commercial model input (set to 941 in 09_Commercial Model)
B14: Conversations handled (Zavis CRM) | C14: 4122 | E14: Contact-center volume is real; routing discipline matters
B16: B. THE CREATIVE GAP, QUANTIFIED
B17: Measure | C17: Value | E17: Meaning
B18: Actual blended CPL | C18: =C9 -> 361 | E18: Generic search + GMB, no lane offers, no creative testing
B19: Plan CPL (with creative engine) | C19: ='04_Spend Capacity'!D52 -> 161 | E19: Requires lane offers + creative pod + video/UGC — the wearefast.io unlocks
B20: Y1 lead plan cost at ACTUAL CPL | C20: ='04_Spend Capacity'!H19*C18 -> 7834422 | E20: 21,702 paid QLs × actual CPL — what Y1 costs if nothing changes
B21: Y1 lead plan cost at PLAN CPL | C21: ='04_Spend Capacity'!D19 -> 3494022 | E21: The modelled envelope
B22: ANNUAL VALUE OF THE CREATIVE UNLOCK | C22: =C20-C21 -> 4340400 | E22: The efficiency gap wearefast.io's creative unlocks are worth per year — before counting volume upside
B24: C. GO-FORWARD CHANNEL TRACKER (update at each sync)
B25: Channel | C25: Status | D25: Plan leads/mo | E25: Plan CPL | F25: Actual spend MTD | G25: Actual leads MTD | H25: Actual CPL | I25: Note
B26: Google Search + GMB (Al Wasl, generic) | C26: ACTIVE | D26: 300 | E26: 200 | F26: 0 | G26: 0 | H26: =IF(G26>0,ROUND(F26/G26,0),0) -> 0 | I26: Only live paid engine today; expected to improve once lane LPs replace generic
B27: Lane-based paid (B/D/C offers) | C27: PARKED | D27: 700 | E27: 145 | F27: 0 | G27: 0 | H27: =IF(G27>0,ROUND(F27/G27,0),0) -> 0 | I27: Blocked on creative — resume trigger: wearefast.io design pod + first asset batch
B28: Meta Ads (lane reels/carousels) | C28: PARKED | D28: 525 | E28: 160 | F28: 0 | G28: 0 | H28: =IF(G28>0,ROUND(F28/G28,0),0) -> 0 | I28: Blocked on creative; lanes currently run ORGANIC social only
B29: ArabyAds (affiliate/influencer CPL) | C29: STARTING | D29: 525 | E29: 120 | F29: 0 | G29: 0 | H29: =IF(G29>0,ROUND(F29/G29,0),0) -> 0 | I29: Execution starts next week; CPL-based
B30: Reactivation (WA blasts) | C30: ACTIVE | D30: 375 | E30: 40 | F30: 0 | G30: 0 | H30: =IF(G30>0,ROUND(F30/G30,0),0) -> 0 | I30: Lanie + clinic managers; Zavis CRM
B31: B2B / referrals | C31: PARTIAL | D31: 375 | E31: 60 | F31: 0 | G31: 0 | H31: =IF(G31>0,ROUND(F31/G31,0),0) -> 0 | I31: Commercial Lead; pilot list
B33: Data-quality asks for the growth room: (1) source-tag every booking so lead→booking is measurable per channel; (2) confirm the period behind 'appointments completed = 39' before reading a show rate; (3) split Meta vs Google in the spend line going forward.

Sheet 11_Clinic Capacity
B2: CLINIC CAPACITY & MEDIA THROTTLE RULES
B3: Demand must never outrun chairs. Two views: current rescue-phase network and the annual network model.
B5: CURRENT PHASE — 3-CLINIC RESCUE NETWORK (per 02_Lane Model)
B6: Clinic | C6: Leads/mo | D6: Patients/mo | E6: Rev/mo (AED) | F6: Utilisation now | G6: Target | H6: Capacity action
B7: Dr. Tosun | C7: 1000 | D7: 200 | E7: 200000 | F7: 60% | G7: 75–85% | H7: Add 20 slots/day if utilisation exceeds 85%
B8: DN Al Wasl | C8: 1000 | D8: 200 | E8: 200000 | F8: 20% | G8: 50% | H8: Biggest opportunity — 80% empty. Protect 25 consult slots/wk + CBCT blocks; enforce 45–60 min consults
B9: AMC | C9: 500 | D9: 100 | E9: 100000 | F9: 40% | G9: 65% | H9: Hard-protect 10 emergency slots/day; overflow branch if wait > 2 hours
B11: ANNUAL NETWORK MODEL — 4-BRANCH VIEW (Y1 plan; DIFC + Fairmont ramp in)
B12: Branch | C12: Q1 | D12: Q2 | E12: Q3 | F12: Q4 | G12: Y1 patients | H12: Community / media routing
B13: Al Wasl (Acacia/DN) | C13: 1125 | D13: 1285 | E13: 2811 | F13: 3093 | G13: =SUM(C13:F13) -> 8314 | H13: Emirati & family demand — route search + GBP demand here first; flagship proof
B14: Dr Tosun | C14: 1807 | D14: 2008 | E14: 2209 | F14: 2410 | G14: =SUM(C14:F14) -> 8434 | H14: Turkish diaspora + premium specialist — language-native messaging & retargeting
B15: DIFC (launch) | C15: 0 | D15: 964 | E15: 1687 | F15: 1928 | G15: =SUM(C15:F15) -> 4579 | H15: Finance/legal expats — unlock only after routing & capacity readiness
B16: Russian (Fairmont) | C16: 643 | D16: 1125 | E16: 1285 | F16: 1607 | G16: =SUM(C16:F16) -> 4660 | H16: Russian expats & tourists — multilingual proof + concierge routing
B17: Network total | C17: =SUM(C13:C16) -> 3575 | D17: =SUM(D13:D16) -> 5382 | E17: =SUM(E13:E16) -> 7992 | F17: =SUM(F13:F16) -> 9038 | G17: =SUM(G13:G16) -> 25987 | H17: Controls Y1 new-patient math and paid pacing
B19: Reconciliation note: the rescue phase runs today's 3 clinics (Tosun / Al Wasl / AMC); the annual model adds DIFC (launching) and Fairmont ramp. AMC demand folds into the network plan as emergency-lane primary. Both views are intentional — near-term ops vs full-year network.
B21: THROTTLE RULES
B22: Trigger | D22: Action
B23: Occupancy > 85% at a clinic | D23: Throttle that clinic's demand or reroute to lower-occupancy clinic
B24: Show rate below target | D24: Fix reminders / deposits / scripting before scaling that clinic's spend
B25: Response SLA fails (missed leads) | D25: Pause paid for that clinic until reception/TC recovery is verified
B26: New clinic opens / routing changes | D26: Run split tests by clinic and language before full budget shift

Sheet 12_KPIs & Governance
B2: KPIs, GUARDRAILS & CADENCE
B4: CORE KPIs
B5: KPI | C5: Target | D5: Why it matters
B6: Qualified leads / month | C6: 2,500 (by lane per 02_Lane Model) | D6: Primary volume indicator
B7: Lead → booking | C7: ≥ 60% (Rescue protocol) | D7: Front desk 5-min response + mandatory script
B8: Show rate | C8: ≥ 70–80% by lane | D8: Drives ~20% lead→patient economics
B9: Treatment acceptance | C9: ≥ 48% group / ≥50% Lane C | D9: TC discipline; financing offers
B10: Revenue / month | C10: AED 500,000 (AED 6M run rate) | D10: The number the lanes back into
B11: Net CPL (blended) | C11: ≤ AED 150 by Month 6 | D11: Gates OOH and scale decisions
B12: WhatsApp response speed (Lane D) | C12: ≤ 2 minutes | D12: Emergency lane wins on speed
B13: Review volume & rating | C13: ≥ 4.6★; +1,000 reviews Y1 | D13: Trust engine; substitutes for parked PR
B15: SPEND GUARDRAILS
B16: Action | C16: Trigger | D16: Response
B17: Pause | C17: Channel ROMI < 1.5x for 2 consecutive weeks | D17: Rebuild creative/targeting before respend
B18: Scale | C18: ROMI > 3x AND clinic occupancy < 85% | D18: Shift budget to winner within monthly envelope
B19: Throttle | C19: Occupancy > 85% | D19: Protect chair capacity even if ROMI is strong
B21: CADENCE WITH PARTNERS
B22: Rhythm | C22: What happens | D22: Who
B23: Daily (Rescue phase) | C23: 09:00 huddle: lead flow by clinic/lane; scale winners, pause losers | D23: Dr. Luvi + Fahad + Lanie
B24: Weekly | C24: Async performance update (dashboard link + 08_Actuals vs plan) | D24: DN sends; no meeting required
B25: Bi-weekly | C25: wearefast.io sync: unlock progress, park register review | D25: Faisal + DN growth lead
B26: Monthly | C26: Budget gate: release next month's envelope vs guardrails | D26: Mr. Akbar (CEO) + Faisal sign-off
B27: Quarterly | C27: Plan re-base: scenarios in 04_Spend Capacity revisited | D27: Full review
B28: Weekly (ArabyAds) | C28: CPL + lead-quality review (booking rate by source tag); pause/scale placements | D28: Fahad + ArabyAds account lead
B30: DECISION PROTOCOL (GREEN / AMBER / RED / REDEPLOY)
B31: Signal | C31: Condition | D31: Action
B32: GREEN | C32: CPL, lead quality, show rate and clinic capacity all inside guardrail | D32: Scale the channel/offer
B33: AMBER | C33: CPL 0–20% above target or one conversion stage weak but solvable this sprint | D33: Hold and rebuild
B34: RED | C34: CPL >20% above target 2 weeks, or compliance/tracking/capacity blocks safe execution | D34: Pause or park with resume trigger
B35: REDEPLOY | C35: Any park event | D35: Shift budget/time to Search, GBP/local, reactivation, or live offer lanes
B37: FIRST PARTNER MEETING AGENDA (FAISAL)
B38: 1. Confirm operating scenario: Conservative / BASE / Aggressive (04_Spend Capacity).
B39: 2. Confirm wearefast.io unlock owners + start months: design pod, video/podcast studio, UGC production (06_wearefast Unlocks).
B40: 3. Review ArabyAds launch readiness for next week: creative feed, source tagging, CPL quality guardrail.
B41: 4. Agree first 90-day channel sequence and spend tranche release rules.
B42: 5. Lock weekly growth-room dashboard + park-register review cadence.

Sheet 13_Assumptions & Sources
B2: ASSUMPTIONS & SOURCES
B4: Operating model | C4: Revenue Rescue Plan (5-lane parallel execution): 2,500 leads/mo → 60% book → 70% show → 48% accept → 500 patients → AED 500K/mo at 1,000 AED avg revenue per patient. Clinics: Dr. Tosun 1,000 · Al Wasl 1,000 · AMC 500.
B5: Funnel consistency | C5: Rescue funnel ≈20.2% lead→patient; Y1 annual model uses 20% QL→arrival (25% book × 80% show). Two independent builds converge — conversion economics validated.
B6: Lane shares | C6: Lane B Family 35% · Lane D Emergency 20% · Lane C Implants 20% · Lane J Ortho 20% · Lane E Lifestyle 5%. Hook offers per Rescue plan lane sheets.
B7: Channel mix | C7: Digital 70% (Google 40% / Meta 30% / Influencer 30% of digital) · Reactivation 15% · B2B 15%. Owners: Fahad+agency / Lanie+managers / Commercial Lead.
B8: Weighted paid CPL | C8: AED 161 blended (Y1 model): Search 140, PMax 150, Meta CTWA 170, Meta Lead Ads 140, TikTok 160, YouTube 320. Target ≤150 by M6. Channel working targets in 10_Actuals Tracker are consistent with this blend.
B9: Paid share taper | C9: Q1 65% → Q4 50% of QLs as organic engines ramp.
B10: Monthly paid figures | C10: From Year1_Cost sheet of the Y1 plan workbook (M1 168,406 → M12 371,105; Y1 ≈ AED 3.49M).
B11: One-time costs | C11: From 10_Costs_OneTime (AED 360,000). Agency onboarding line (150K) is negotiable scope within the wearefast.io engagement.
B12: Fixed stack | C12: AED 14,350/month: hosting, sGTM, call tracking & DNI, WA platform fees, SEO/review tools.
B13: Governance (RACI) | C13: Accountable: Dr. Luvi. Strategy & approval: Mr. Akbar (CEO). Execution: Fahad (marketing), Lanie (front desk/ops), Gautam (TMO, deadlines). wearefast.io plugs into the Fahad workstream.
B14: Park logic | C14: Founder decision: blocked initiatives are parked with resume triggers, never allowed to stall the programme.
B15: ArabyAds program | C15: Contracted affiliate/influencer/demand-gen partner on a CPL model; execution begins next week. Covers influencer ACTIVATION and affiliate lead volume within the Digital 70% envelope; creative production is supplied by wearefast.io; all leads land in DN tracking with source tags for independent quality measurement (booking-rate guardrail ≥40%).
B17: SOURCE FILES
B18: DentalNation_Y1_ComprehensivePlan_v1.xlsx | C18: Spend capacity, funnel math, channel CPLs, roadmap, resourcing, one-time costs.
B19: Revenue Rescue Plan (Mar 2026 deck) | C19: 5-lane model, clinic/channel allocation, hook offers, funnel rates, RACI, capacity utilisation.
B20: ChatGPT draft workbook (Y1 Marketing Unlock Plan) | C20: Canonical offer names, Anchor–Ladder targets, phase labels, decision protocol — adopted with corrections (high-value mix fix; radiographic→videography; Assembly→wearefast.io; ArabyAds added).
B21: Founder Operating Brief | C21: Positioning: brand-led, platform-powered consumer-health dental company; masterbrand + clinic ladder.
B22: Growth Hub / Growth Master Plan | C22: Initiative blockers used to seed the park register.
